[2022-12-08T03:17:20.769+0000] {taskinstance.py:1087} INFO - Dependencies all met for <TaskInstance: streamify_dag.wait_in_scanner_line_create_external_table scheduled__2022-12-08T02:05:00+00:00 [queued]>
[2022-12-08T03:17:20.781+0000] {taskinstance.py:1087} INFO - Dependencies all met for <TaskInstance: streamify_dag.wait_in_scanner_line_create_external_table scheduled__2022-12-08T02:05:00+00:00 [queued]>
[2022-12-08T03:17:20.782+0000] {taskinstance.py:1283} INFO - 
--------------------------------------------------------------------------------
[2022-12-08T03:17:20.782+0000] {taskinstance.py:1284} INFO - Starting attempt 1 of 1
[2022-12-08T03:17:20.782+0000] {taskinstance.py:1285} INFO - 
--------------------------------------------------------------------------------
[2022-12-08T03:17:20.810+0000] {taskinstance.py:1304} INFO - Executing <Task(BigQueryCreateExternalTableOperator): wait_in_scanner_line_create_external_table> on 2022-12-08 02:05:00+00:00
[2022-12-08T03:17:20.819+0000] {standard_task_runner.py:55} INFO - Started process 224 to run task
[2022-12-08T03:17:20.831+0000] {standard_task_runner.py:82} INFO - Running: ['***', 'tasks', 'run', 'streamify_dag', 'wait_in_scanner_line_create_external_table', 'scheduled__2022-12-08T02:05:00+00:00', '--job-id', '3', '--raw', '--subdir', 'DAGS_FOLDER/ticketsim.py', '--cfg-path', '/tmp/tmpdz4avehj']
[2022-12-08T03:17:20.838+0000] {standard_task_runner.py:83} INFO - Job 3: Subtask wait_in_scanner_line_create_external_table
[2022-12-08T03:17:20.970+0000] {task_command.py:389} INFO - Running <TaskInstance: streamify_dag.wait_in_scanner_line_create_external_table scheduled__2022-12-08T02:05:00+00:00 [running]> on host 6d1412fc1d7e
[2022-12-08T03:17:21.111+0000] {taskinstance.py:1513} INFO - Exporting the following env vars:
AIRFLOW_CTX_DAG_OWNER=***
AIRFLOW_CTX_DAG_ID=streamify_dag
AIRFLOW_CTX_TASK_ID=wait_in_scanner_line_create_external_table
AIRFLOW_CTX_EXECUTION_DATE=2022-12-08T02:05:00+00:00
AIRFLOW_CTX_TRY_NUMBER=1
AIRFLOW_CTX_DAG_RUN_ID=scheduled__2022-12-08T02:05:00+00:00
[2022-12-08T03:17:21.114+0000] {crypto.py:83} WARNING - empty cryptography key - values will not be stored encrypted.
[2022-12-08T03:17:21.115+0000] {base.py:73} INFO - Using connection ID 'google_cloud_default' for task execution.
[2022-12-08T03:17:21.116+0000] {taskinstance.py:1772} ERROR - Task failed with exception
Traceback (most recent call last):
  File "/home/airflow/.local/lib/python3.7/site-packages/airflow/providers/google/cloud/operators/bigquery.py", line 1592, in execute
    table_resource=self.table_resource,
  File "/home/airflow/.local/lib/python3.7/site-packages/airflow/providers/google/common/hooks/base_google.py", line 455, in inner_wrapper
    kwargs["project_id"] = self.project_id
  File "/home/airflow/.local/lib/python3.7/site-packages/airflow/providers/google/common/hooks/base_google.py", line 342, in project_id
    _, project_id = self.get_credentials_and_project_id()
  File "/home/airflow/.local/lib/python3.7/site-packages/airflow/providers/google/common/hooks/base_google.py", line 261, in get_credentials_and_project_id
    delegates=delegates,
  File "/home/airflow/.local/lib/python3.7/site-packages/airflow/providers/google/cloud/utils/credentials_provider.py", line 332, in get_credentials_and_project_id
    return _CredentialProvider(*args, **kwargs).get_credentials_and_project()
  File "/home/airflow/.local/lib/python3.7/site-packages/airflow/providers/google/cloud/utils/credentials_provider.py", line 231, in get_credentials_and_project
    credentials, project_id = self._get_credentials_using_key_path()
  File "/home/airflow/.local/lib/python3.7/site-packages/airflow/providers/google/cloud/utils/credentials_provider.py", line 281, in _get_credentials_using_key_path
    self.key_path, scopes=self.scopes
  File "/home/airflow/.local/lib/python3.7/site-packages/google/oauth2/service_account.py", line 242, in from_service_account_file
    filename, require=["client_email", "token_uri"]
  File "/home/airflow/.local/lib/python3.7/site-packages/google/auth/_service_account_info.py", line 79, in from_filename
    with io.open(filename, "r", encoding="utf-8") as json_file:
FileNotFoundError: [Errno 2] No such file or directory: '/.google/credentials/google_credentials.json'
[2022-12-08T03:17:21.133+0000] {taskinstance.py:1327} INFO - Marking task as FAILED. dag_id=streamify_dag, task_id=wait_in_scanner_line_create_external_table, execution_date=20221208T020500, start_date=20221208T031720, end_date=20221208T031721
[2022-12-08T03:17:21.164+0000] {standard_task_runner.py:105} ERROR - Failed to execute job 3 for task wait_in_scanner_line_create_external_table ([Errno 2] No such file or directory: '/.google/credentials/google_credentials.json'; 224)
[2022-12-08T03:17:21.200+0000] {local_task_job.py:159} INFO - Task exited with return code 1
[2022-12-08T03:17:21.233+0000] {taskinstance.py:2582} INFO - 0 downstream tasks scheduled from follow-on schedule check
[2022-12-08T03:30:54.350+0000] {taskinstance.py:1087} INFO - Dependencies all met for <TaskInstance: streamify_dag.wait_in_scanner_line_create_external_table scheduled__2022-12-08T02:05:00+00:00 [queued]>
[2022-12-08T03:30:54.369+0000] {taskinstance.py:1087} INFO - Dependencies all met for <TaskInstance: streamify_dag.wait_in_scanner_line_create_external_table scheduled__2022-12-08T02:05:00+00:00 [queued]>
[2022-12-08T03:30:54.369+0000] {taskinstance.py:1283} INFO - 
--------------------------------------------------------------------------------
[2022-12-08T03:30:54.369+0000] {taskinstance.py:1284} INFO - Starting attempt 1 of 1
[2022-12-08T03:30:54.369+0000] {taskinstance.py:1285} INFO - 
--------------------------------------------------------------------------------
[2022-12-08T03:30:54.389+0000] {taskinstance.py:1304} INFO - Executing <Task(BigQueryCreateExternalTableOperator): wait_in_scanner_line_create_external_table> on 2022-12-08 02:05:00+00:00
[2022-12-08T03:30:54.399+0000] {standard_task_runner.py:55} INFO - Started process 138 to run task
[2022-12-08T03:30:54.406+0000] {standard_task_runner.py:82} INFO - Running: ['***', 'tasks', 'run', 'streamify_dag', 'wait_in_scanner_line_create_external_table', 'scheduled__2022-12-08T02:05:00+00:00', '--job-id', '3', '--raw', '--subdir', 'DAGS_FOLDER/ticketsim.py', '--cfg-path', '/tmp/tmprkc5jh14']
[2022-12-08T03:30:54.409+0000] {standard_task_runner.py:83} INFO - Job 3: Subtask wait_in_scanner_line_create_external_table
[2022-12-08T03:30:54.514+0000] {task_command.py:389} INFO - Running <TaskInstance: streamify_dag.wait_in_scanner_line_create_external_table scheduled__2022-12-08T02:05:00+00:00 [running]> on host 8dc4e4d2ec7a
[2022-12-08T03:30:54.626+0000] {taskinstance.py:1513} INFO - Exporting the following env vars:
AIRFLOW_CTX_DAG_OWNER=***
AIRFLOW_CTX_DAG_ID=streamify_dag
AIRFLOW_CTX_TASK_ID=wait_in_scanner_line_create_external_table
AIRFLOW_CTX_EXECUTION_DATE=2022-12-08T02:05:00+00:00
AIRFLOW_CTX_TRY_NUMBER=1
AIRFLOW_CTX_DAG_RUN_ID=scheduled__2022-12-08T02:05:00+00:00
[2022-12-08T03:30:54.629+0000] {crypto.py:83} WARNING - empty cryptography key - values will not be stored encrypted.
[2022-12-08T03:30:54.630+0000] {base.py:73} INFO - Using connection ID 'google_cloud_default' for task execution.
[2022-12-08T03:30:54.641+0000] {taskinstance.py:1772} ERROR - Task failed with exception
Traceback (most recent call last):
  File "/home/airflow/.local/lib/python3.7/site-packages/airflow/providers/google/cloud/operators/bigquery.py", line 1592, in execute
    table_resource=self.table_resource,
  File "/home/airflow/.local/lib/python3.7/site-packages/airflow/providers/google/common/hooks/base_google.py", line 462, in inner_wrapper
    return func(self, *args, **kwargs)
  File "/home/airflow/.local/lib/python3.7/site-packages/airflow/providers/google/cloud/hooks/bigquery.py", line 399, in create_empty_table
    table_id=table_id,
  File "/home/airflow/.local/lib/python3.7/site-packages/airflow/providers/google/cloud/hooks/bigquery.py", line 195, in _resolve_table_reference
    TableReference.from_api_repr(table_resource["tableReference"])
  File "/home/airflow/.local/lib/python3.7/site-packages/google/cloud/bigquery/table.py", line 279, in from_api_repr
    return cls(DatasetReference(project, dataset_id), table_id)
  File "/home/airflow/.local/lib/python3.7/site-packages/google/cloud/bigquery/dataset.py", line 260, in __init__
    raise ValueError("Pass a string for project")
ValueError: Pass a string for project
[2022-12-08T03:30:54.665+0000] {taskinstance.py:1327} INFO - Marking task as FAILED. dag_id=streamify_dag, task_id=wait_in_scanner_line_create_external_table, execution_date=20221208T020500, start_date=20221208T033054, end_date=20221208T033054
[2022-12-08T03:30:54.690+0000] {standard_task_runner.py:105} ERROR - Failed to execute job 3 for task wait_in_scanner_line_create_external_table (Pass a string for project; 138)
[2022-12-08T03:30:54.738+0000] {local_task_job.py:159} INFO - Task exited with return code 1
[2022-12-08T03:30:54.766+0000] {taskinstance.py:2582} INFO - 0 downstream tasks scheduled from follow-on schedule check
[2022-12-08T03:38:17.828+0000] {taskinstance.py:1087} INFO - Dependencies all met for <TaskInstance: streamify_dag.wait_in_scanner_line_create_external_table scheduled__2022-12-08T02:05:00+00:00 [queued]>
[2022-12-08T03:38:17.849+0000] {taskinstance.py:1087} INFO - Dependencies all met for <TaskInstance: streamify_dag.wait_in_scanner_line_create_external_table scheduled__2022-12-08T02:05:00+00:00 [queued]>
[2022-12-08T03:38:17.849+0000] {taskinstance.py:1283} INFO - 
--------------------------------------------------------------------------------
[2022-12-08T03:38:17.850+0000] {taskinstance.py:1284} INFO - Starting attempt 1 of 1
[2022-12-08T03:38:17.850+0000] {taskinstance.py:1285} INFO - 
--------------------------------------------------------------------------------
[2022-12-08T03:38:17.877+0000] {taskinstance.py:1304} INFO - Executing <Task(BigQueryCreateExternalTableOperator): wait_in_scanner_line_create_external_table> on 2022-12-08 02:05:00+00:00
[2022-12-08T03:38:17.887+0000] {standard_task_runner.py:55} INFO - Started process 124 to run task
[2022-12-08T03:38:17.897+0000] {standard_task_runner.py:82} INFO - Running: ['***', 'tasks', 'run', 'streamify_dag', 'wait_in_scanner_line_create_external_table', 'scheduled__2022-12-08T02:05:00+00:00', '--job-id', '4', '--raw', '--subdir', 'DAGS_FOLDER/ticketsim.py', '--cfg-path', '/tmp/tmp4lxotcu4']
[2022-12-08T03:38:17.901+0000] {standard_task_runner.py:83} INFO - Job 4: Subtask wait_in_scanner_line_create_external_table
[2022-12-08T03:38:17.999+0000] {task_command.py:389} INFO - Running <TaskInstance: streamify_dag.wait_in_scanner_line_create_external_table scheduled__2022-12-08T02:05:00+00:00 [running]> on host 1222418420bc
[2022-12-08T03:38:18.207+0000] {taskinstance.py:1513} INFO - Exporting the following env vars:
AIRFLOW_CTX_DAG_OWNER=***
AIRFLOW_CTX_DAG_ID=streamify_dag
AIRFLOW_CTX_TASK_ID=wait_in_scanner_line_create_external_table
AIRFLOW_CTX_EXECUTION_DATE=2022-12-08T02:05:00+00:00
AIRFLOW_CTX_TRY_NUMBER=1
AIRFLOW_CTX_DAG_RUN_ID=scheduled__2022-12-08T02:05:00+00:00
[2022-12-08T03:38:18.210+0000] {crypto.py:83} WARNING - empty cryptography key - values will not be stored encrypted.
[2022-12-08T03:38:18.211+0000] {base.py:73} INFO - Using connection ID 'google_cloud_default' for task execution.
[2022-12-08T03:38:18.906+0000] {taskinstance.py:1772} ERROR - Task failed with exception
Traceback (most recent call last):
  File "/home/airflow/.local/lib/python3.7/site-packages/airflow/providers/google/cloud/operators/bigquery.py", line 1592, in execute
    table_resource=self.table_resource,
  File "/home/airflow/.local/lib/python3.7/site-packages/airflow/providers/google/common/hooks/base_google.py", line 462, in inner_wrapper
    return func(self, *args, **kwargs)
  File "/home/airflow/.local/lib/python3.7/site-packages/airflow/providers/google/cloud/hooks/bigquery.py", line 403, in create_empty_table
    table=table, exists_ok=exists_ok, retry=retry
  File "/home/airflow/.local/lib/python3.7/site-packages/google/cloud/bigquery/client.py", line 755, in create_table
    timeout=timeout,
  File "/home/airflow/.local/lib/python3.7/site-packages/google/cloud/bigquery/client.py", line 782, in _call_api
    return call()
  File "/home/airflow/.local/lib/python3.7/site-packages/google/api_core/retry.py", line 288, in retry_wrapped_func
    on_error=on_error,
  File "/home/airflow/.local/lib/python3.7/site-packages/google/api_core/retry.py", line 190, in retry_target
    return target()
  File "/home/airflow/.local/lib/python3.7/site-packages/google/cloud/_http/__init__.py", line 494, in api_request
    raise exceptions.from_http_response(response)
google.api_core.exceptions.NotFound: 404 POST https://bigquery.googleapis.com/bigquery/v2/projects/elite-bird-367213/datasets/ticketsim/tables?prettyPrint=false: Not found: Dataset elite-bird-367213:ticketsim
[2022-12-08T03:38:18.940+0000] {taskinstance.py:1327} INFO - Marking task as FAILED. dag_id=streamify_dag, task_id=wait_in_scanner_line_create_external_table, execution_date=20221208T020500, start_date=20221208T033817, end_date=20221208T033818
[2022-12-08T03:38:18.978+0000] {standard_task_runner.py:105} ERROR - Failed to execute job 4 for task wait_in_scanner_line_create_external_table (404 POST https://bigquery.googleapis.com/bigquery/v2/projects/elite-bird-367213/datasets/ticketsim/tables?prettyPrint=false: Not found: Dataset elite-bird-367213:ticketsim; 124)
[2022-12-08T03:38:18.999+0000] {local_task_job.py:159} INFO - Task exited with return code 1
[2022-12-08T03:38:19.048+0000] {taskinstance.py:2582} INFO - 0 downstream tasks scheduled from follow-on schedule check
[2022-12-08T03:48:49.207+0000] {taskinstance.py:1087} INFO - Dependencies all met for <TaskInstance: streamify_dag.wait_in_scanner_line_create_external_table scheduled__2022-12-08T02:05:00+00:00 [queued]>
[2022-12-08T03:48:49.226+0000] {taskinstance.py:1087} INFO - Dependencies all met for <TaskInstance: streamify_dag.wait_in_scanner_line_create_external_table scheduled__2022-12-08T02:05:00+00:00 [queued]>
[2022-12-08T03:48:49.226+0000] {taskinstance.py:1283} INFO - 
--------------------------------------------------------------------------------
[2022-12-08T03:48:49.227+0000] {taskinstance.py:1284} INFO - Starting attempt 1 of 1
[2022-12-08T03:48:49.227+0000] {taskinstance.py:1285} INFO - 
--------------------------------------------------------------------------------
[2022-12-08T03:48:49.256+0000] {taskinstance.py:1304} INFO - Executing <Task(BigQueryCreateExternalTableOperator): wait_in_scanner_line_create_external_table> on 2022-12-08 02:05:00+00:00
[2022-12-08T03:48:49.267+0000] {standard_task_runner.py:55} INFO - Started process 116 to run task
[2022-12-08T03:48:49.277+0000] {standard_task_runner.py:82} INFO - Running: ['***', 'tasks', 'run', 'streamify_dag', 'wait_in_scanner_line_create_external_table', 'scheduled__2022-12-08T02:05:00+00:00', '--job-id', '4', '--raw', '--subdir', 'DAGS_FOLDER/ticketsim.py', '--cfg-path', '/tmp/tmpvmgq867b']
[2022-12-08T03:48:49.281+0000] {standard_task_runner.py:83} INFO - Job 4: Subtask wait_in_scanner_line_create_external_table
[2022-12-08T03:48:49.427+0000] {task_command.py:389} INFO - Running <TaskInstance: streamify_dag.wait_in_scanner_line_create_external_table scheduled__2022-12-08T02:05:00+00:00 [running]> on host 4181f20faf08
[2022-12-08T03:48:49.600+0000] {taskinstance.py:1513} INFO - Exporting the following env vars:
AIRFLOW_CTX_DAG_OWNER=***
AIRFLOW_CTX_DAG_ID=streamify_dag
AIRFLOW_CTX_TASK_ID=wait_in_scanner_line_create_external_table
AIRFLOW_CTX_EXECUTION_DATE=2022-12-08T02:05:00+00:00
AIRFLOW_CTX_TRY_NUMBER=1
AIRFLOW_CTX_DAG_RUN_ID=scheduled__2022-12-08T02:05:00+00:00
[2022-12-08T03:48:49.607+0000] {crypto.py:83} WARNING - empty cryptography key - values will not be stored encrypted.
[2022-12-08T03:48:49.608+0000] {base.py:73} INFO - Using connection ID 'google_cloud_default' for task execution.
[2022-12-08T03:48:52.678+0000] {taskinstance.py:1327} INFO - Marking task as SUCCESS. dag_id=streamify_dag, task_id=wait_in_scanner_line_create_external_table, execution_date=20221208T020500, start_date=20221208T034849, end_date=20221208T034852
[2022-12-08T03:48:52.710+0000] {local_task_job.py:159} INFO - Task exited with return code 0
[2022-12-08T03:48:52.739+0000] {taskinstance.py:2582} INFO - 0 downstream tasks scheduled from follow-on schedule check
[2022-12-08T03:56:26.300+0000] {taskinstance.py:1087} INFO - Dependencies all met for <TaskInstance: streamify_dag.wait_in_scanner_line_create_external_table scheduled__2022-12-08T02:05:00+00:00 [queued]>
[2022-12-08T03:56:26.316+0000] {taskinstance.py:1087} INFO - Dependencies all met for <TaskInstance: streamify_dag.wait_in_scanner_line_create_external_table scheduled__2022-12-08T02:05:00+00:00 [queued]>
[2022-12-08T03:56:26.316+0000] {taskinstance.py:1283} INFO - 
--------------------------------------------------------------------------------
[2022-12-08T03:56:26.317+0000] {taskinstance.py:1284} INFO - Starting attempt 1 of 1
[2022-12-08T03:56:26.317+0000] {taskinstance.py:1285} INFO - 
--------------------------------------------------------------------------------
[2022-12-08T03:56:26.342+0000] {taskinstance.py:1304} INFO - Executing <Task(BigQueryCreateExternalTableOperator): wait_in_scanner_line_create_external_table> on 2022-12-08 02:05:00+00:00
[2022-12-08T03:56:26.361+0000] {standard_task_runner.py:55} INFO - Started process 114 to run task
[2022-12-08T03:56:26.368+0000] {standard_task_runner.py:82} INFO - Running: ['***', 'tasks', 'run', 'streamify_dag', 'wait_in_scanner_line_create_external_table', 'scheduled__2022-12-08T02:05:00+00:00', '--job-id', '3', '--raw', '--subdir', 'DAGS_FOLDER/ticketsim.py', '--cfg-path', '/tmp/tmpkm04ly78']
[2022-12-08T03:56:26.372+0000] {standard_task_runner.py:83} INFO - Job 3: Subtask wait_in_scanner_line_create_external_table
[2022-12-08T03:56:26.476+0000] {task_command.py:389} INFO - Running <TaskInstance: streamify_dag.wait_in_scanner_line_create_external_table scheduled__2022-12-08T02:05:00+00:00 [running]> on host 91631708998d
[2022-12-08T03:56:26.581+0000] {taskinstance.py:1513} INFO - Exporting the following env vars:
AIRFLOW_CTX_DAG_OWNER=***
AIRFLOW_CTX_DAG_ID=streamify_dag
AIRFLOW_CTX_TASK_ID=wait_in_scanner_line_create_external_table
AIRFLOW_CTX_EXECUTION_DATE=2022-12-08T02:05:00+00:00
AIRFLOW_CTX_TRY_NUMBER=1
AIRFLOW_CTX_DAG_RUN_ID=scheduled__2022-12-08T02:05:00+00:00
[2022-12-08T03:56:26.584+0000] {crypto.py:83} WARNING - empty cryptography key - values will not be stored encrypted.
[2022-12-08T03:56:26.584+0000] {base.py:73} INFO - Using connection ID 'google_cloud_default' for task execution.
[2022-12-08T03:56:26.966+0000] {taskinstance.py:1772} ERROR - Task failed with exception
Traceback (most recent call last):
  File "/home/airflow/.local/lib/python3.7/site-packages/airflow/providers/google/cloud/operators/bigquery.py", line 1592, in execute
    table_resource=self.table_resource,
  File "/home/airflow/.local/lib/python3.7/site-packages/airflow/providers/google/common/hooks/base_google.py", line 462, in inner_wrapper
    return func(self, *args, **kwargs)
  File "/home/airflow/.local/lib/python3.7/site-packages/airflow/providers/google/cloud/hooks/bigquery.py", line 403, in create_empty_table
    table=table, exists_ok=exists_ok, retry=retry
  File "/home/airflow/.local/lib/python3.7/site-packages/google/cloud/bigquery/client.py", line 755, in create_table
    timeout=timeout,
  File "/home/airflow/.local/lib/python3.7/site-packages/google/cloud/bigquery/client.py", line 782, in _call_api
    return call()
  File "/home/airflow/.local/lib/python3.7/site-packages/google/api_core/retry.py", line 288, in retry_wrapped_func
    on_error=on_error,
  File "/home/airflow/.local/lib/python3.7/site-packages/google/api_core/retry.py", line 190, in retry_target
    return target()
  File "/home/airflow/.local/lib/python3.7/site-packages/google/cloud/_http/__init__.py", line 494, in api_request
    raise exceptions.from_http_response(response)
google.api_core.exceptions.NotFound: 404 POST https://bigquery.googleapis.com/bigquery/v2/projects/elite-bird-367213/datasets/ticketsim/tables?prettyPrint=false: Not found: Dataset elite-bird-367213:ticketsim
[2022-12-08T03:56:26.981+0000] {taskinstance.py:1327} INFO - Marking task as FAILED. dag_id=streamify_dag, task_id=wait_in_scanner_line_create_external_table, execution_date=20221208T020500, start_date=20221208T035626, end_date=20221208T035626
[2022-12-08T03:56:26.999+0000] {standard_task_runner.py:105} ERROR - Failed to execute job 3 for task wait_in_scanner_line_create_external_table (404 POST https://bigquery.googleapis.com/bigquery/v2/projects/elite-bird-367213/datasets/ticketsim/tables?prettyPrint=false: Not found: Dataset elite-bird-367213:ticketsim; 114)
[2022-12-08T03:56:27.020+0000] {local_task_job.py:159} INFO - Task exited with return code 1
[2022-12-08T03:56:27.048+0000] {taskinstance.py:2582} INFO - 0 downstream tasks scheduled from follow-on schedule check
