[2022-12-08T03:17:25.512+0000] {taskinstance.py:1087} INFO - Dependencies all met for <TaskInstance: streamify_dag.wait_in_scanner_line_create_external_table manual__2022-12-08T03:17:16.208399+00:00 [queued]>
[2022-12-08T03:17:25.531+0000] {taskinstance.py:1087} INFO - Dependencies all met for <TaskInstance: streamify_dag.wait_in_scanner_line_create_external_table manual__2022-12-08T03:17:16.208399+00:00 [queued]>
[2022-12-08T03:17:25.531+0000] {taskinstance.py:1283} INFO - 
--------------------------------------------------------------------------------
[2022-12-08T03:17:25.532+0000] {taskinstance.py:1284} INFO - Starting attempt 1 of 1
[2022-12-08T03:17:25.532+0000] {taskinstance.py:1285} INFO - 
--------------------------------------------------------------------------------
[2022-12-08T03:17:25.555+0000] {taskinstance.py:1304} INFO - Executing <Task(BigQueryCreateExternalTableOperator): wait_in_scanner_line_create_external_table> on 2022-12-08 03:17:16.208399+00:00
[2022-12-08T03:17:25.565+0000] {standard_task_runner.py:55} INFO - Started process 231 to run task
[2022-12-08T03:17:25.575+0000] {standard_task_runner.py:82} INFO - Running: ['***', 'tasks', 'run', 'streamify_dag', 'wait_in_scanner_line_create_external_table', 'manual__2022-12-08T03:17:16.208399+00:00', '--job-id', '6', '--raw', '--subdir', 'DAGS_FOLDER/ticketsim.py', '--cfg-path', '/tmp/tmpkqfepw5r']
[2022-12-08T03:17:25.580+0000] {standard_task_runner.py:83} INFO - Job 6: Subtask wait_in_scanner_line_create_external_table
[2022-12-08T03:17:25.718+0000] {task_command.py:389} INFO - Running <TaskInstance: streamify_dag.wait_in_scanner_line_create_external_table manual__2022-12-08T03:17:16.208399+00:00 [running]> on host 6d1412fc1d7e
[2022-12-08T03:17:25.882+0000] {taskinstance.py:1513} INFO - Exporting the following env vars:
AIRFLOW_CTX_DAG_OWNER=***
AIRFLOW_CTX_DAG_ID=streamify_dag
AIRFLOW_CTX_TASK_ID=wait_in_scanner_line_create_external_table
AIRFLOW_CTX_EXECUTION_DATE=2022-12-08T03:17:16.208399+00:00
AIRFLOW_CTX_TRY_NUMBER=1
AIRFLOW_CTX_DAG_RUN_ID=manual__2022-12-08T03:17:16.208399+00:00
[2022-12-08T03:17:25.885+0000] {crypto.py:83} WARNING - empty cryptography key - values will not be stored encrypted.
[2022-12-08T03:17:25.886+0000] {base.py:73} INFO - Using connection ID 'google_cloud_default' for task execution.
[2022-12-08T03:17:25.887+0000] {taskinstance.py:1772} ERROR - Task failed with exception
Traceback (most recent call last):
  File "/home/airflow/.local/lib/python3.7/site-packages/airflow/providers/google/cloud/operators/bigquery.py", line 1592, in execute
    table_resource=self.table_resource,
  File "/home/airflow/.local/lib/python3.7/site-packages/airflow/providers/google/common/hooks/base_google.py", line 455, in inner_wrapper
    kwargs["project_id"] = self.project_id
  File "/home/airflow/.local/lib/python3.7/site-packages/airflow/providers/google/common/hooks/base_google.py", line 342, in project_id
    _, project_id = self.get_credentials_and_project_id()
  File "/home/airflow/.local/lib/python3.7/site-packages/airflow/providers/google/common/hooks/base_google.py", line 261, in get_credentials_and_project_id
    delegates=delegates,
  File "/home/airflow/.local/lib/python3.7/site-packages/airflow/providers/google/cloud/utils/credentials_provider.py", line 332, in get_credentials_and_project_id
    return _CredentialProvider(*args, **kwargs).get_credentials_and_project()
  File "/home/airflow/.local/lib/python3.7/site-packages/airflow/providers/google/cloud/utils/credentials_provider.py", line 231, in get_credentials_and_project
    credentials, project_id = self._get_credentials_using_key_path()
  File "/home/airflow/.local/lib/python3.7/site-packages/airflow/providers/google/cloud/utils/credentials_provider.py", line 281, in _get_credentials_using_key_path
    self.key_path, scopes=self.scopes
  File "/home/airflow/.local/lib/python3.7/site-packages/google/oauth2/service_account.py", line 242, in from_service_account_file
    filename, require=["client_email", "token_uri"]
  File "/home/airflow/.local/lib/python3.7/site-packages/google/auth/_service_account_info.py", line 79, in from_filename
    with io.open(filename, "r", encoding="utf-8") as json_file:
FileNotFoundError: [Errno 2] No such file or directory: '/.google/credentials/google_credentials.json'
[2022-12-08T03:17:25.902+0000] {taskinstance.py:1327} INFO - Marking task as FAILED. dag_id=streamify_dag, task_id=wait_in_scanner_line_create_external_table, execution_date=20221208T031716, start_date=20221208T031725, end_date=20221208T031725
[2022-12-08T03:17:25.927+0000] {standard_task_runner.py:105} ERROR - Failed to execute job 6 for task wait_in_scanner_line_create_external_table ([Errno 2] No such file or directory: '/.google/credentials/google_credentials.json'; 231)
[2022-12-08T03:17:25.947+0000] {local_task_job.py:159} INFO - Task exited with return code 1
[2022-12-08T03:17:25.983+0000] {taskinstance.py:2582} INFO - 0 downstream tasks scheduled from follow-on schedule check
