[2022-12-08T03:17:20.774+0000] {taskinstance.py:1087} INFO - Dependencies all met for <TaskInstance: streamify_dag.wait_in_seller_line_create_external_table scheduled__2022-12-08T02:05:00+00:00 [queued]>
[2022-12-08T03:17:20.788+0000] {taskinstance.py:1087} INFO - Dependencies all met for <TaskInstance: streamify_dag.wait_in_seller_line_create_external_table scheduled__2022-12-08T02:05:00+00:00 [queued]>
[2022-12-08T03:17:20.789+0000] {taskinstance.py:1283} INFO - 
--------------------------------------------------------------------------------
[2022-12-08T03:17:20.789+0000] {taskinstance.py:1284} INFO - Starting attempt 1 of 1
[2022-12-08T03:17:20.789+0000] {taskinstance.py:1285} INFO - 
--------------------------------------------------------------------------------
[2022-12-08T03:17:20.820+0000] {taskinstance.py:1304} INFO - Executing <Task(BigQueryCreateExternalTableOperator): wait_in_seller_line_create_external_table> on 2022-12-08 02:05:00+00:00
[2022-12-08T03:17:20.830+0000] {standard_task_runner.py:55} INFO - Started process 225 to run task
[2022-12-08T03:17:20.838+0000] {standard_task_runner.py:82} INFO - Running: ['***', 'tasks', 'run', 'streamify_dag', 'wait_in_seller_line_create_external_table', 'scheduled__2022-12-08T02:05:00+00:00', '--job-id', '4', '--raw', '--subdir', 'DAGS_FOLDER/ticketsim.py', '--cfg-path', '/tmp/tmpr6kzdg7r']
[2022-12-08T03:17:20.842+0000] {standard_task_runner.py:83} INFO - Job 4: Subtask wait_in_seller_line_create_external_table
[2022-12-08T03:17:20.968+0000] {task_command.py:389} INFO - Running <TaskInstance: streamify_dag.wait_in_seller_line_create_external_table scheduled__2022-12-08T02:05:00+00:00 [running]> on host 6d1412fc1d7e
[2022-12-08T03:17:21.104+0000] {taskinstance.py:1513} INFO - Exporting the following env vars:
AIRFLOW_CTX_DAG_OWNER=***
AIRFLOW_CTX_DAG_ID=streamify_dag
AIRFLOW_CTX_TASK_ID=wait_in_seller_line_create_external_table
AIRFLOW_CTX_EXECUTION_DATE=2022-12-08T02:05:00+00:00
AIRFLOW_CTX_TRY_NUMBER=1
AIRFLOW_CTX_DAG_RUN_ID=scheduled__2022-12-08T02:05:00+00:00
[2022-12-08T03:17:21.109+0000] {crypto.py:83} WARNING - empty cryptography key - values will not be stored encrypted.
[2022-12-08T03:17:21.109+0000] {base.py:73} INFO - Using connection ID 'google_cloud_default' for task execution.
[2022-12-08T03:17:21.111+0000] {taskinstance.py:1772} ERROR - Task failed with exception
Traceback (most recent call last):
  File "/home/airflow/.local/lib/python3.7/site-packages/airflow/providers/google/cloud/operators/bigquery.py", line 1592, in execute
    table_resource=self.table_resource,
  File "/home/airflow/.local/lib/python3.7/site-packages/airflow/providers/google/common/hooks/base_google.py", line 455, in inner_wrapper
    kwargs["project_id"] = self.project_id
  File "/home/airflow/.local/lib/python3.7/site-packages/airflow/providers/google/common/hooks/base_google.py", line 342, in project_id
    _, project_id = self.get_credentials_and_project_id()
  File "/home/airflow/.local/lib/python3.7/site-packages/airflow/providers/google/common/hooks/base_google.py", line 261, in get_credentials_and_project_id
    delegates=delegates,
  File "/home/airflow/.local/lib/python3.7/site-packages/airflow/providers/google/cloud/utils/credentials_provider.py", line 332, in get_credentials_and_project_id
    return _CredentialProvider(*args, **kwargs).get_credentials_and_project()
  File "/home/airflow/.local/lib/python3.7/site-packages/airflow/providers/google/cloud/utils/credentials_provider.py", line 231, in get_credentials_and_project
    credentials, project_id = self._get_credentials_using_key_path()
  File "/home/airflow/.local/lib/python3.7/site-packages/airflow/providers/google/cloud/utils/credentials_provider.py", line 281, in _get_credentials_using_key_path
    self.key_path, scopes=self.scopes
  File "/home/airflow/.local/lib/python3.7/site-packages/google/oauth2/service_account.py", line 242, in from_service_account_file
    filename, require=["client_email", "token_uri"]
  File "/home/airflow/.local/lib/python3.7/site-packages/google/auth/_service_account_info.py", line 79, in from_filename
    with io.open(filename, "r", encoding="utf-8") as json_file:
FileNotFoundError: [Errno 2] No such file or directory: '/.google/credentials/google_credentials.json'
[2022-12-08T03:17:21.134+0000] {taskinstance.py:1327} INFO - Marking task as FAILED. dag_id=streamify_dag, task_id=wait_in_seller_line_create_external_table, execution_date=20221208T020500, start_date=20221208T031720, end_date=20221208T031721
[2022-12-08T03:17:21.153+0000] {standard_task_runner.py:105} ERROR - Failed to execute job 4 for task wait_in_seller_line_create_external_table ([Errno 2] No such file or directory: '/.google/credentials/google_credentials.json'; 225)
[2022-12-08T03:17:21.171+0000] {local_task_job.py:159} INFO - Task exited with return code 1
[2022-12-08T03:17:21.201+0000] {taskinstance.py:2582} INFO - 0 downstream tasks scheduled from follow-on schedule check
[2022-12-08T03:30:54.359+0000] {taskinstance.py:1087} INFO - Dependencies all met for <TaskInstance: streamify_dag.wait_in_seller_line_create_external_table scheduled__2022-12-08T02:05:00+00:00 [queued]>
[2022-12-08T03:30:54.374+0000] {taskinstance.py:1087} INFO - Dependencies all met for <TaskInstance: streamify_dag.wait_in_seller_line_create_external_table scheduled__2022-12-08T02:05:00+00:00 [queued]>
[2022-12-08T03:30:54.374+0000] {taskinstance.py:1283} INFO - 
--------------------------------------------------------------------------------
[2022-12-08T03:30:54.375+0000] {taskinstance.py:1284} INFO - Starting attempt 1 of 1
[2022-12-08T03:30:54.375+0000] {taskinstance.py:1285} INFO - 
--------------------------------------------------------------------------------
[2022-12-08T03:30:54.394+0000] {taskinstance.py:1304} INFO - Executing <Task(BigQueryCreateExternalTableOperator): wait_in_seller_line_create_external_table> on 2022-12-08 02:05:00+00:00
[2022-12-08T03:30:54.403+0000] {standard_task_runner.py:55} INFO - Started process 139 to run task
[2022-12-08T03:30:54.410+0000] {standard_task_runner.py:82} INFO - Running: ['***', 'tasks', 'run', 'streamify_dag', 'wait_in_seller_line_create_external_table', 'scheduled__2022-12-08T02:05:00+00:00', '--job-id', '4', '--raw', '--subdir', 'DAGS_FOLDER/ticketsim.py', '--cfg-path', '/tmp/tmp5xtusg4b']
[2022-12-08T03:30:54.414+0000] {standard_task_runner.py:83} INFO - Job 4: Subtask wait_in_seller_line_create_external_table
[2022-12-08T03:30:54.514+0000] {task_command.py:389} INFO - Running <TaskInstance: streamify_dag.wait_in_seller_line_create_external_table scheduled__2022-12-08T02:05:00+00:00 [running]> on host 8dc4e4d2ec7a
[2022-12-08T03:30:54.622+0000] {taskinstance.py:1513} INFO - Exporting the following env vars:
AIRFLOW_CTX_DAG_OWNER=***
AIRFLOW_CTX_DAG_ID=streamify_dag
AIRFLOW_CTX_TASK_ID=wait_in_seller_line_create_external_table
AIRFLOW_CTX_EXECUTION_DATE=2022-12-08T02:05:00+00:00
AIRFLOW_CTX_TRY_NUMBER=1
AIRFLOW_CTX_DAG_RUN_ID=scheduled__2022-12-08T02:05:00+00:00
[2022-12-08T03:30:54.625+0000] {crypto.py:83} WARNING - empty cryptography key - values will not be stored encrypted.
[2022-12-08T03:30:54.626+0000] {base.py:73} INFO - Using connection ID 'google_cloud_default' for task execution.
[2022-12-08T03:30:54.642+0000] {taskinstance.py:1772} ERROR - Task failed with exception
Traceback (most recent call last):
  File "/home/airflow/.local/lib/python3.7/site-packages/airflow/providers/google/cloud/operators/bigquery.py", line 1592, in execute
    table_resource=self.table_resource,
  File "/home/airflow/.local/lib/python3.7/site-packages/airflow/providers/google/common/hooks/base_google.py", line 462, in inner_wrapper
    return func(self, *args, **kwargs)
  File "/home/airflow/.local/lib/python3.7/site-packages/airflow/providers/google/cloud/hooks/bigquery.py", line 399, in create_empty_table
    table_id=table_id,
  File "/home/airflow/.local/lib/python3.7/site-packages/airflow/providers/google/cloud/hooks/bigquery.py", line 195, in _resolve_table_reference
    TableReference.from_api_repr(table_resource["tableReference"])
  File "/home/airflow/.local/lib/python3.7/site-packages/google/cloud/bigquery/table.py", line 279, in from_api_repr
    return cls(DatasetReference(project, dataset_id), table_id)
  File "/home/airflow/.local/lib/python3.7/site-packages/google/cloud/bigquery/dataset.py", line 260, in __init__
    raise ValueError("Pass a string for project")
ValueError: Pass a string for project
[2022-12-08T03:30:54.664+0000] {taskinstance.py:1327} INFO - Marking task as FAILED. dag_id=streamify_dag, task_id=wait_in_seller_line_create_external_table, execution_date=20221208T020500, start_date=20221208T033054, end_date=20221208T033054
[2022-12-08T03:30:54.687+0000] {standard_task_runner.py:105} ERROR - Failed to execute job 4 for task wait_in_seller_line_create_external_table (Pass a string for project; 139)
[2022-12-08T03:30:54.701+0000] {local_task_job.py:159} INFO - Task exited with return code 1
[2022-12-08T03:30:54.734+0000] {taskinstance.py:2582} INFO - 0 downstream tasks scheduled from follow-on schedule check
[2022-12-08T03:38:17.830+0000] {taskinstance.py:1087} INFO - Dependencies all met for <TaskInstance: streamify_dag.wait_in_seller_line_create_external_table scheduled__2022-12-08T02:05:00+00:00 [queued]>
[2022-12-08T03:38:17.851+0000] {taskinstance.py:1087} INFO - Dependencies all met for <TaskInstance: streamify_dag.wait_in_seller_line_create_external_table scheduled__2022-12-08T02:05:00+00:00 [queued]>
[2022-12-08T03:38:17.851+0000] {taskinstance.py:1283} INFO - 
--------------------------------------------------------------------------------
[2022-12-08T03:38:17.852+0000] {taskinstance.py:1284} INFO - Starting attempt 1 of 1
[2022-12-08T03:38:17.852+0000] {taskinstance.py:1285} INFO - 
--------------------------------------------------------------------------------
[2022-12-08T03:38:17.874+0000] {taskinstance.py:1304} INFO - Executing <Task(BigQueryCreateExternalTableOperator): wait_in_seller_line_create_external_table> on 2022-12-08 02:05:00+00:00
[2022-12-08T03:38:17.885+0000] {standard_task_runner.py:55} INFO - Started process 123 to run task
[2022-12-08T03:38:17.892+0000] {standard_task_runner.py:82} INFO - Running: ['***', 'tasks', 'run', 'streamify_dag', 'wait_in_seller_line_create_external_table', 'scheduled__2022-12-08T02:05:00+00:00', '--job-id', '3', '--raw', '--subdir', 'DAGS_FOLDER/ticketsim.py', '--cfg-path', '/tmp/tmpbfywbbrm']
[2022-12-08T03:38:17.896+0000] {standard_task_runner.py:83} INFO - Job 3: Subtask wait_in_seller_line_create_external_table
[2022-12-08T03:38:18.023+0000] {task_command.py:389} INFO - Running <TaskInstance: streamify_dag.wait_in_seller_line_create_external_table scheduled__2022-12-08T02:05:00+00:00 [running]> on host 1222418420bc
[2022-12-08T03:38:18.215+0000] {taskinstance.py:1513} INFO - Exporting the following env vars:
AIRFLOW_CTX_DAG_OWNER=***
AIRFLOW_CTX_DAG_ID=streamify_dag
AIRFLOW_CTX_TASK_ID=wait_in_seller_line_create_external_table
AIRFLOW_CTX_EXECUTION_DATE=2022-12-08T02:05:00+00:00
AIRFLOW_CTX_TRY_NUMBER=1
AIRFLOW_CTX_DAG_RUN_ID=scheduled__2022-12-08T02:05:00+00:00
[2022-12-08T03:38:18.218+0000] {crypto.py:83} WARNING - empty cryptography key - values will not be stored encrypted.
[2022-12-08T03:38:18.219+0000] {base.py:73} INFO - Using connection ID 'google_cloud_default' for task execution.
[2022-12-08T03:38:18.875+0000] {taskinstance.py:1772} ERROR - Task failed with exception
Traceback (most recent call last):
  File "/home/airflow/.local/lib/python3.7/site-packages/airflow/providers/google/cloud/operators/bigquery.py", line 1592, in execute
    table_resource=self.table_resource,
  File "/home/airflow/.local/lib/python3.7/site-packages/airflow/providers/google/common/hooks/base_google.py", line 462, in inner_wrapper
    return func(self, *args, **kwargs)
  File "/home/airflow/.local/lib/python3.7/site-packages/airflow/providers/google/cloud/hooks/bigquery.py", line 403, in create_empty_table
    table=table, exists_ok=exists_ok, retry=retry
  File "/home/airflow/.local/lib/python3.7/site-packages/google/cloud/bigquery/client.py", line 755, in create_table
    timeout=timeout,
  File "/home/airflow/.local/lib/python3.7/site-packages/google/cloud/bigquery/client.py", line 782, in _call_api
    return call()
  File "/home/airflow/.local/lib/python3.7/site-packages/google/api_core/retry.py", line 288, in retry_wrapped_func
    on_error=on_error,
  File "/home/airflow/.local/lib/python3.7/site-packages/google/api_core/retry.py", line 190, in retry_target
    return target()
  File "/home/airflow/.local/lib/python3.7/site-packages/google/cloud/_http/__init__.py", line 494, in api_request
    raise exceptions.from_http_response(response)
google.api_core.exceptions.NotFound: 404 POST https://bigquery.googleapis.com/bigquery/v2/projects/elite-bird-367213/datasets/ticketsim/tables?prettyPrint=false: Not found: Dataset elite-bird-367213:ticketsim
[2022-12-08T03:38:18.928+0000] {taskinstance.py:1327} INFO - Marking task as FAILED. dag_id=streamify_dag, task_id=wait_in_seller_line_create_external_table, execution_date=20221208T020500, start_date=20221208T033817, end_date=20221208T033818
[2022-12-08T03:38:18.960+0000] {standard_task_runner.py:105} ERROR - Failed to execute job 3 for task wait_in_seller_line_create_external_table (404 POST https://bigquery.googleapis.com/bigquery/v2/projects/elite-bird-367213/datasets/ticketsim/tables?prettyPrint=false: Not found: Dataset elite-bird-367213:ticketsim; 123)
[2022-12-08T03:38:18.991+0000] {local_task_job.py:159} INFO - Task exited with return code 1
[2022-12-08T03:38:19.025+0000] {taskinstance.py:2582} INFO - 0 downstream tasks scheduled from follow-on schedule check
[2022-12-08T03:48:49.172+0000] {taskinstance.py:1087} INFO - Dependencies all met for <TaskInstance: streamify_dag.wait_in_seller_line_create_external_table scheduled__2022-12-08T02:05:00+00:00 [queued]>
[2022-12-08T03:48:49.192+0000] {taskinstance.py:1087} INFO - Dependencies all met for <TaskInstance: streamify_dag.wait_in_seller_line_create_external_table scheduled__2022-12-08T02:05:00+00:00 [queued]>
[2022-12-08T03:48:49.192+0000] {taskinstance.py:1283} INFO - 
--------------------------------------------------------------------------------
[2022-12-08T03:48:49.192+0000] {taskinstance.py:1284} INFO - Starting attempt 1 of 1
[2022-12-08T03:48:49.193+0000] {taskinstance.py:1285} INFO - 
--------------------------------------------------------------------------------
[2022-12-08T03:48:49.222+0000] {taskinstance.py:1304} INFO - Executing <Task(BigQueryCreateExternalTableOperator): wait_in_seller_line_create_external_table> on 2022-12-08 02:05:00+00:00
[2022-12-08T03:48:49.233+0000] {standard_task_runner.py:55} INFO - Started process 115 to run task
[2022-12-08T03:48:49.246+0000] {standard_task_runner.py:82} INFO - Running: ['***', 'tasks', 'run', 'streamify_dag', 'wait_in_seller_line_create_external_table', 'scheduled__2022-12-08T02:05:00+00:00', '--job-id', '3', '--raw', '--subdir', 'DAGS_FOLDER/ticketsim.py', '--cfg-path', '/tmp/tmpfzwzozde']
[2022-12-08T03:48:49.253+0000] {standard_task_runner.py:83} INFO - Job 3: Subtask wait_in_seller_line_create_external_table
[2022-12-08T03:48:49.460+0000] {task_command.py:389} INFO - Running <TaskInstance: streamify_dag.wait_in_seller_line_create_external_table scheduled__2022-12-08T02:05:00+00:00 [running]> on host 4181f20faf08
[2022-12-08T03:48:49.634+0000] {taskinstance.py:1513} INFO - Exporting the following env vars:
AIRFLOW_CTX_DAG_OWNER=***
AIRFLOW_CTX_DAG_ID=streamify_dag
AIRFLOW_CTX_TASK_ID=wait_in_seller_line_create_external_table
AIRFLOW_CTX_EXECUTION_DATE=2022-12-08T02:05:00+00:00
AIRFLOW_CTX_TRY_NUMBER=1
AIRFLOW_CTX_DAG_RUN_ID=scheduled__2022-12-08T02:05:00+00:00
[2022-12-08T03:48:49.638+0000] {crypto.py:83} WARNING - empty cryptography key - values will not be stored encrypted.
[2022-12-08T03:48:49.642+0000] {base.py:73} INFO - Using connection ID 'google_cloud_default' for task execution.
[2022-12-08T03:48:51.731+0000] {taskinstance.py:1327} INFO - Marking task as SUCCESS. dag_id=streamify_dag, task_id=wait_in_seller_line_create_external_table, execution_date=20221208T020500, start_date=20221208T034849, end_date=20221208T034851
[2022-12-08T03:48:51.792+0000] {local_task_job.py:159} INFO - Task exited with return code 0
[2022-12-08T03:48:51.818+0000] {taskinstance.py:2582} INFO - 0 downstream tasks scheduled from follow-on schedule check
[2022-12-08T03:56:26.301+0000] {taskinstance.py:1087} INFO - Dependencies all met for <TaskInstance: streamify_dag.wait_in_seller_line_create_external_table scheduled__2022-12-08T02:05:00+00:00 [queued]>
[2022-12-08T03:56:26.320+0000] {taskinstance.py:1087} INFO - Dependencies all met for <TaskInstance: streamify_dag.wait_in_seller_line_create_external_table scheduled__2022-12-08T02:05:00+00:00 [queued]>
[2022-12-08T03:56:26.321+0000] {taskinstance.py:1283} INFO - 
--------------------------------------------------------------------------------
[2022-12-08T03:56:26.321+0000] {taskinstance.py:1284} INFO - Starting attempt 1 of 1
[2022-12-08T03:56:26.321+0000] {taskinstance.py:1285} INFO - 
--------------------------------------------------------------------------------
[2022-12-08T03:56:26.350+0000] {taskinstance.py:1304} INFO - Executing <Task(BigQueryCreateExternalTableOperator): wait_in_seller_line_create_external_table> on 2022-12-08 02:05:00+00:00
[2022-12-08T03:56:26.359+0000] {standard_task_runner.py:55} INFO - Started process 115 to run task
[2022-12-08T03:56:26.369+0000] {standard_task_runner.py:82} INFO - Running: ['***', 'tasks', 'run', 'streamify_dag', 'wait_in_seller_line_create_external_table', 'scheduled__2022-12-08T02:05:00+00:00', '--job-id', '4', '--raw', '--subdir', 'DAGS_FOLDER/ticketsim.py', '--cfg-path', '/tmp/tmp1lpf1wbf']
[2022-12-08T03:56:26.373+0000] {standard_task_runner.py:83} INFO - Job 4: Subtask wait_in_seller_line_create_external_table
[2022-12-08T03:56:26.478+0000] {task_command.py:389} INFO - Running <TaskInstance: streamify_dag.wait_in_seller_line_create_external_table scheduled__2022-12-08T02:05:00+00:00 [running]> on host 91631708998d
[2022-12-08T03:56:26.582+0000] {taskinstance.py:1513} INFO - Exporting the following env vars:
AIRFLOW_CTX_DAG_OWNER=***
AIRFLOW_CTX_DAG_ID=streamify_dag
AIRFLOW_CTX_TASK_ID=wait_in_seller_line_create_external_table
AIRFLOW_CTX_EXECUTION_DATE=2022-12-08T02:05:00+00:00
AIRFLOW_CTX_TRY_NUMBER=1
AIRFLOW_CTX_DAG_RUN_ID=scheduled__2022-12-08T02:05:00+00:00
[2022-12-08T03:56:26.585+0000] {crypto.py:83} WARNING - empty cryptography key - values will not be stored encrypted.
[2022-12-08T03:56:26.586+0000] {base.py:73} INFO - Using connection ID 'google_cloud_default' for task execution.
[2022-12-08T03:56:26.993+0000] {taskinstance.py:1772} ERROR - Task failed with exception
Traceback (most recent call last):
  File "/home/airflow/.local/lib/python3.7/site-packages/airflow/providers/google/cloud/operators/bigquery.py", line 1592, in execute
    table_resource=self.table_resource,
  File "/home/airflow/.local/lib/python3.7/site-packages/airflow/providers/google/common/hooks/base_google.py", line 462, in inner_wrapper
    return func(self, *args, **kwargs)
  File "/home/airflow/.local/lib/python3.7/site-packages/airflow/providers/google/cloud/hooks/bigquery.py", line 403, in create_empty_table
    table=table, exists_ok=exists_ok, retry=retry
  File "/home/airflow/.local/lib/python3.7/site-packages/google/cloud/bigquery/client.py", line 755, in create_table
    timeout=timeout,
  File "/home/airflow/.local/lib/python3.7/site-packages/google/cloud/bigquery/client.py", line 782, in _call_api
    return call()
  File "/home/airflow/.local/lib/python3.7/site-packages/google/api_core/retry.py", line 288, in retry_wrapped_func
    on_error=on_error,
  File "/home/airflow/.local/lib/python3.7/site-packages/google/api_core/retry.py", line 190, in retry_target
    return target()
  File "/home/airflow/.local/lib/python3.7/site-packages/google/cloud/_http/__init__.py", line 494, in api_request
    raise exceptions.from_http_response(response)
google.api_core.exceptions.NotFound: 404 POST https://bigquery.googleapis.com/bigquery/v2/projects/elite-bird-367213/datasets/ticketsim/tables?prettyPrint=false: Not found: Dataset elite-bird-367213:ticketsim
[2022-12-08T03:56:27.007+0000] {taskinstance.py:1327} INFO - Marking task as FAILED. dag_id=streamify_dag, task_id=wait_in_seller_line_create_external_table, execution_date=20221208T020500, start_date=20221208T035626, end_date=20221208T035627
[2022-12-08T03:56:27.028+0000] {standard_task_runner.py:105} ERROR - Failed to execute job 4 for task wait_in_seller_line_create_external_table (404 POST https://bigquery.googleapis.com/bigquery/v2/projects/elite-bird-367213/datasets/ticketsim/tables?prettyPrint=false: Not found: Dataset elite-bird-367213:ticketsim; 115)
[2022-12-08T03:56:27.062+0000] {local_task_job.py:159} INFO - Task exited with return code 1
[2022-12-08T03:56:27.088+0000] {taskinstance.py:2582} INFO - 0 downstream tasks scheduled from follow-on schedule check
